<?xml version='1.0' encoding='utf-8'?>
<robot name="human_36dof_ISB_model">
    <material name="body_color">
        <color rgba="0.0 0.0 0.8 1.0" />
    </material>
    <material name="body_color_R">
        <color rgba="0.8 0.0 0.0 1.0" />
    </material>
     <material name="body_color_L">
        <color rgba="0.0 0.8 0.0 1.0" />
    </material>
    <link name="middle_pelvis">
        <inertial>
            <mass value="10.65" />
            <origin xyz="0.03 -0.025 -0.001" rpy="0 -0 0" />
            <inertia ixx="0.08977" ixy="-0.0055" ixz="-0.00127" iyy="0.09888" iyz="-0.00056" izz="0.07942" />
        </inertial>
        <visual>
	        <origin xyz="0.0 -0.05 0.0" rpy="0 0 0" />
            <geometry>
		        <mesh filename="meshes/pelvis_mesh.STL" scale="0.0063 0.0058 0.0058" />
            </geometry>
            <material name="body_color" />
        </visual>
    </link>
    <joint name="left_hip_Z" type="revolute">
        <origin xyz="0.023 -0.1 -0.082" rpy="0 -0 0" />
        <axis xyz="0 0 1" />
        <parent link="middle_pelvis" />
        <child link="left_upperleg_virtual" />
        <limit effort="185" velocity="12.0" lower="-1.047196667" upper="3.14159" />
    </joint>
    <link name="left_upperleg_virtual" />
    <joint name="left_hip_X" type="revolute">
        <origin xyz="0 0 0" rpy="0 -0 0" />
        <axis xyz="1 0 0" />
        <parent link="left_upperleg_virtual" />
        <child link="left_upperleg_virtual_2" />
        <limit effort="120" velocity="12.0" lower="-1.047196667" upper="1.570795" />
    </joint>
    <link name="left_upperleg_virtual_2" />
    <joint name="left_hip_Y" type="revolute">
        <origin xyz="0 0 0" rpy="0 -0 0" />
        <axis xyz="0 -1 0" />
        <parent link="left_upperleg_virtual_2" />
        <child link="left_upperleg" />
        <limit effort="60" velocity="12.0" lower="-1.570795" upper="1.047196667" />
    </joint>
    <link name="left_upperleg">
        <inertial>
            <mass value="9.22" />
            <origin xyz="-0.018 -0.188 0.014" rpy="0 -0 0" />
            <inertia ixx="0.1497" ixy="0.00872" ixz="-0.00071" iyy="0.04005" iyz="-0.00872" izz="0.1602" />
        </inertial>
        <visual>
            <origin xyz="0 -0.05 0.0" rpy="0.0 0 0" />
            <geometry>
                <mesh filename="meshes/upperleg_mesh.STL" scale="0.0062 0.0064 0.0069" />
            </geometry>
            <material name="body_color_L" />
        </visual>
    </link>
    <joint name="left_knee_Z" type="revolute">
        <origin xyz="0. -0.439 0." rpy="0 -0 0" />
        <axis xyz="0 0 -1" />
        <parent link="left_upperleg" />
        <child link="left_lowerleg" />
        <limit effort="130" velocity="18.6" lower="0" upper="3.14159" />
    </joint>
    <link name="left_lowerleg">
        <inertial>
            <mass value="3.6" />
            <origin xyz="-0.021 -0.181 0.003" rpy="0 -0 0" />
            <inertia ixx="0.05471" ixy="0.00112" ixz="0.00028" iyy="0.00698" iyz="0.00174" izz="0.05471" />
        </inertial>
        <visual>
            <origin xyz="-0.0 -0.0 0.0" rpy="0.0 0.0 0" />
            <geometry>
                <mesh filename="meshes/lowerleg_mesh.STL" scale="0.0063 0.0066 0.007" />
            </geometry>
            <material name="body_color_L" />
	    </visual>
        <visual>
            <origin xyz="-0.0 0.0 -0.0" rpy="0 -0 0" />
            <geometry>
                <mesh filename="meshes/knee_mesh.STL" scale="0.0056 0.0056 0.0056" />
            </geometry>
            <material name="body_color_L" />
        </visual>
    </link>
    <joint name="left_ankle_Z" type="revolute">
        <origin xyz="0 -0.44 0" rpy="0 -0 0" />
        <axis xyz="0 0 1" />
        <parent link="left_lowerleg" />
        <child link="left_foot_virtual" />
        <limit effort="126" velocity="12.7" lower="-1.570795" upper="0.7853975" />
    </joint>
    <link name="left_foot_virtual" />
    <joint name="left_ankle_X" type="revolute">
        <origin xyz="0 0 0" rpy="0 -0 0" />
        <axis xyz="-1 0 0" />
        <parent link="left_foot_virtual" />
        <child link="left_foot" />
        <limit effort="20" velocity="2.0" lower="-0.523598333" upper="0.785398" />
    </joint>
    <link name="left_foot">
        <inertial>
            <mass value="0.9" />
            <origin xyz="0.068 -0.027 0.005" rpy="0 -0 0" />
            <inertia ixx="0.00081" ixy="0.00048" ixz="-0.00018" iyy="0.00385" iyz="0.0" izz="0.00364" />
        </inertial>
        <visual>
            <origin xyz="-0.0 -0.0 0.00" rpy="0 0 0" />
            <geometry>
		        <mesh filename="meshes/foot_mesh.STL" scale="0.0067 0.0067 0.0067" />
                
            </geometry>
            <material name="body_color_L" />
        </visual>
    </link>
    <joint name="middle_lumbar_Z" type="revolute">
        <origin xyz="0 0 0" rpy="0 -0 0" />
        <axis xyz="0 0 -1" />
        <parent link="middle_pelvis" />
        <child link="middle_abdomen_virtual" />
        <limit effort="190" velocity="5.2" lower="-0.785398" upper="3.14159" />
    </joint>
    <link name="middle_abdomen_virtual" />
    <joint name="middle_lumbar_X" type="revolute">
        <origin xyz="0 0 0" rpy="0 -0 0" />
        <axis xyz="1 0 0" />
        <parent link="middle_abdomen_virtual" />
        <child link="middle_abdomen" />
        <limit effort="160" velocity="5.2" lower="-0.785398" upper="0.785398" />
    </joint>
    <link name="middle_abdomen">
        <inertial>
            <mass value="12.25" />
            <origin xyz="-0.008 0.1 0.0" rpy="0 -0 0" />
            <inertia ixx="0.04427" ixy="0.01968" ixz="-0.00024" iyy="0.03796" iyz="-0.00097" izz="0.04761" />
        </inertial>
        <visual>
            <origin xyz="-0.0 0.0 -0.0" rpy="0 -0 0" />
            <geometry>
		        <mesh filename="meshes/abdomen_mesh.STL" scale="0.0074 0.0074 0.0074" />
                
            </geometry>
            <material name="body_color" />
        </visual>
    </link>
    <joint name="middle_thoracic_Z" type="revolute">
        <origin xyz="0 0.223 0" rpy="0 -0 0" />
        <axis xyz="0 0 -1" />
        <parent link="middle_abdomen" />
        <child link="middle_thorax_virtual" />
        <limit effort="190" velocity="5.2" lower="-0.392699" upper="1.0472" />
    </joint>
    <link name="middle_thorax_virtual" />
    <joint name="middle_thoracic_X" type="revolute">
        <origin xyz="0 0 0" rpy="0 -0 0" />
        <axis xyz="1 0 0" />
        <parent link="middle_thorax_virtual" />
        <child link="middle_thorax_virtual_2" />
        <limit effort="190" velocity="5.2" lower="-1.0472" upper="1.0472" />
    </joint>
    <link name="middle_thorax_virtual_2" />
    <joint name="middle_thoracic_Y" type="revolute">
        <origin xyz="0 0 0" rpy="0 -0 0" />
        <axis xyz="0 1 0" />
        <parent link="middle_thorax_virtual_2" />
        <child link="middle_thorax" />
        <limit effort="185" velocity="2.0" lower="-1.0472" upper="1.0472" />
    </joint>
    <link name="middle_thorax">
        <inertial>
            <mass value="11.97" />
            <origin xyz="-0.009 0.127 -0.001" rpy="0 -0 0" />
            <inertia ixx="0.05463" ixy="0.02428" ixz="-0.0003" iyy="0.04683" iyz="-0.0012" izz="0.05875" />
        </inertial>
        <visual>
	    <origin xyz="-0.0  -0.188511 0.0" rpy="0 -0 0" />
            <geometry>
		        
		        <mesh filename="meshes/torso_mesh.STL" scale="0.007 0.007 0.007" />
            </geometry>
            <material name="body_color" />
        </visual>
    </link>
    <joint name="middle_cervical_Z" type="revolute">
        <origin xyz="0 0.25 0" rpy="0 -0 0" />
        <axis xyz="0 0 -1" />
        <parent link="middle_thorax" />
        <child link="middle_head_virtual" />
        <limit effort="100" velocity="8.7" lower="-1.5708" upper="1.5708" />
    </joint>
    <link name="middle_head_virtual" />
    <joint name="middle_cervical_X" type="revolute">
        <origin xyz="0 0 0" rpy="0 -0 0" />
        <axis xyz="1 0 0" />
        <parent link="middle_head_virtual" />
        <child link="middle_head_virtual_2" />
        <limit effort="100" velocity="8.7" lower="-1.5708" upper="1.5708" />
    </joint>
    <link name="middle_head_virtual_2" />
    <joint name="middle_cervical_Y" type="revolute">
        <origin xyz="0 0 0" rpy="0 -0 0" />
        <axis xyz="0 1 0" />
        <parent link="middle_head_virtual_2" />
        <child link="middle_head" />
        <limit effort="100" velocity="8.7" lower="-1.5708" upper="1.5708" />
    </joint>
    <link name="middle_head">
        <inertial>
            <mass value="5.03" />
            <origin xyz="-0.015 0.131 0.0" rpy="0 -0 0" />
            <inertia ixx="0.02688" ixy="-0.00227" ixz="-0.00011" iyy="0.01748" iyz="0.00025" izz="0.03046" />
        </inertial>
        <visual>
	        <origin xyz="-0.0 0.00 -0.00" rpy="0 -0 0" />
            <geometry>
		        <mesh filename="meshes/head_mesh.STL" scale="0.0056 0.0056 0.0056" />
            </geometry>
            <material name="body_color" />
        </visual>
        <visual>
	     <origin xyz="-0.0 0.00 -0.00" rpy="0 -0 0" />
            <geometry>
		        <mesh filename="meshes/neck_mesh.STL" scale="0.005 0.005 0.005" />
            </geometry>
            <material name="body_color" />
        </visual>
    </link>
    <joint name="left_clavicle_joint_X" type="revolute">
        <origin xyz="0 0.176 0" rpy="0 -0 0" />
        <axis xyz="1 0 0" />
        <parent link="middle_thorax" />
        <child link="left_clavicle" />
        <limit effort="100" velocity="14.0" lower="-0.349066" upper="1.0472" />
    </joint>
    <link name="left_clavicle">
        <inertial>
            <mass value="0.15600" />
            <origin xyz="-0.011096 0.00637 0.05417" rpy="0 -0 0" />
            <inertia ixx="0.00024" ixy="-0.00002" ixz="-0.00007" iyy="0.00026" iyz="0.00005" izz="0.00004" />
        </inertial>
    </link>
    <joint name="left_shoulder_Z" type="revolute">
        <origin xyz="0.008 -0.075 -0.21" rpy="0 -0 0" />
        <axis xyz="0 0 1" />
        <parent link="left_clavicle" />
        <child link="left_upperarm_virtual" />
        <limit effort="92" velocity="17.6" lower="-3.14159" upper="3.14159" />
    </joint>
    <link name="left_upperarm_virtual" />
    <joint name="left_shoulder_X" type="revolute">
        <origin xyz="0 0 0" rpy="0 -0 0" />
        <axis xyz="1 0 0" />
        <parent link="left_upperarm_virtual" />
        <child link="left_upperarm_virtual_2" />
        <limit effort="71" velocity="6.0" lower="-1.0472" upper="3.14159" />
    </joint>
    <link name="left_upperarm_virtual_2" />
    <joint name="left_shoulder_Y" type="revolute">
        <origin xyz="0 0 0" rpy="0 -0 0" />
        <axis xyz="0 -1 0" />
        <parent link="left_upperarm_virtual_2" />
        <child link="left_upperarm" />
        <limit effort="52" velocity="6.0" lower="-1.5708" upper="3.14159" />
    </joint>
    <link name="left_upperarm">
        <inertial>
            <mass value="1.8" />
            <origin xyz="0.005 -0.125 -0.007" rpy="0 -0 0" />
            <inertia ixx="0.01314" ixy="0.00049" ixz="0.00034" iyy="0.00268" iyz="0.00005" izz="0.014" />
        </inertial>
        <visual>
	         <origin xyz="-0.0 0.00 -0.00" rpy="0 -0 0" />
            <geometry>
		        <mesh filename="meshes/shoulder_mesh.STL" scale="0.0039 0.0039 0.0039" />
            </geometry>
            <material name="body_color_L" />
        </visual>
        <visual>
            <origin xyz="-0.0 0.05 -0.00" rpy="0 -0 0" />
            <geometry>
                <mesh filename="meshes/upperarm_mesh.STL" scale="0.0063 0.006 0.0069" />
            </geometry>
            <material name="body_color_L" />
        </visual>
    </link>
    <joint name="left_elbow_Z" type="revolute">
        <origin xyz="0 -0.276 0" rpy="0 -0 0" />
        <axis xyz="0 0 1" />
        <parent link="left_upperarm" />
        <child link="left_lowerarm_virtual" />
        <limit effort="77" velocity="19.9" lower="0" upper="2.617991667" />
    </joint>
    <link name="left_lowerarm_virtual" />
    <joint name="left_elbow_Y" type="revolute">
        <origin xyz="0 0 0" rpy="0 -0 0" />
        <axis xyz="0 -1 0" />
        <parent link="left_lowerarm_virtual" />
        <child link="left_lowerarm" />
        <limit effort="15" velocity="6.0" lower="-0.349066" upper="3.14159" />
    </joint>
    <link name="left_lowerarm">
        <inertial>
            <mass value="1.28" />
            <origin xyz="0.003 -0.12 0.004" rpy="0 -0 0" />
            <inertia ixx="0.00825" ixy="0.00009" ixz="0.00004" iyy="0.00127" iyz="-0.00067" izz="0.00767" />
        </inertial>
        <visual>
            <origin xyz="-0.0 0.00 -0.00" rpy="0 -0 0" />
            <geometry>
                <mesh filename="meshes/lowerarm_mesh.STL" scale="0.0064 0.0064 0.0064" />
            </geometry>
            <material name="body_color_L" />
        </visual>
        <visual>
	        <origin xyz="-0.0 0.00 -0.00" rpy="0 -0 0" />
            <geometry>
		        <mesh filename="meshes/elbow_mesh.STL" scale="0.0055 0.0055 0.0055" />
            </geometry>
            <material name="body_color_L" />
        </visual>
    </link>
    <joint name="left_wrist_Z" type="revolute">
        <origin xyz="0 -0.287 0" rpy="0 -0 0" />
        <axis xyz="0 0 1" />
        <parent link="left_lowerarm" />
        <child link="left_hand_virtual" />
        <limit effort="185" velocity="25.0" lower="-1.5708" upper="1.5708" />
    </joint>
    <link name="left_hand_virtual" />
    <joint name="left_wrist_X" type="revolute">
        <origin xyz="0 0 0" rpy="0 -0 0" />
        <axis xyz="1 0 0" />
        <parent link="left_hand_virtual" />
        <child link="left_hand" />
        <limit effort="100" velocity="6.0" lower="-0.785398" upper="0.785398" />
    </joint>
    <link name="left_hand">
        <inertial>
            <mass value="0.45" />
            <origin xyz="0.015 -0.153 0.014" rpy="0 -0 0" />
            <inertia ixx="0.00558" ixy="0.00073" ixz="0.00034" iyy="0.00216" iyz="-0.0006" izz="0.0047" />
        </inertial>
        </link>
    <joint name="right_clavicle_joint_X" type="revolute">
        <origin xyz="0 0.176 0" rpy="0 -0 0" />
        <axis xyz="-1 0 0" />
        <parent link="middle_thorax" />
        <child link="right_clavicle" />
        <limit effort="100" velocity="14.0" lower="-0.349066" upper="1.0472" />
    </joint>
    <link name="right_clavicle">
        <inertial>
            <mass value="0.15600" />
            <origin xyz="-0.011096 0.00637 0.05417" rpy="0 -0 0" />
            <inertia ixx="0.00024" ixy="-0.00002" ixz="-0.00007" iyy="0.00026" iyz="0.00005" izz="0.00004" />
        </inertial>
    </link>
    <joint name="right_shoulder_Z" type="revolute">
        <origin xyz="0.008 -0.075 0.21" rpy="0 -0 0" />
        <axis xyz="0 0 1" />
        <parent link="right_clavicle" />
        <child link="right_upperarm_virtual" />
        <limit effort="92" velocity="17.6" lower="-3.14159" upper="3.14159" />
    </joint>
    <link name="right_upperarm_virtual" />
    <joint name="right_shoulder_X" type="revolute">
        <origin xyz="0 0 0" rpy="0 -0 0" />
        <axis xyz="-1 0 0" />
        <parent link="right_upperarm_virtual" />
        <child link="right_upperarm_virtual_2" />
        <limit effort="71" velocity="6.0" lower="-1.0472" upper="3.14159" />
    </joint>
    <link name="right_upperarm_virtual_2" />
    <joint name="right_shoulder_Y" type="revolute">
        <origin xyz="0 0 0" rpy="0 -0 0" />
        <axis xyz="0 1 0" />
        <parent link="right_upperarm_virtual_2" />
        <child link="right_upperarm" />
        <limit effort="52" velocity="6.0" lower="-1.5708" upper="3.14159" />
    </joint>
    <link name="right_upperarm">
        <inertial>
            <mass value="1.8" />
            <origin xyz="0.005 -0.125 -0.007" rpy="0 -0 0" />
            <inertia ixx="0.01314" ixy="0.00049" ixz="0.00034" iyy="0.00268" iyz="0.00005" izz="0.014" />
        </inertial>
        <visual>
	        <origin xyz="-0.0 0.0 -0.0" rpy="0 -0 0" />
            <geometry>
		        <mesh filename="meshes/shoulder_mesh.STL" scale="0.0039 0.0039 0.0039" />
            </geometry>
            <material name="body_color_R" />
        </visual>
        <visual>
            <origin xyz="-0.0 0.05 -0.00" rpy="0 -0 0" />
            <geometry>
                <mesh filename="meshes/upperarm_mesh.STL" scale="0.0063 0.006 0.0069" />
            </geometry>
            <material name="body_color_R" />
        </visual>
    </link>
    <joint name="right_elbow_Z" type="revolute">
        <origin xyz="0 -0.276 0" rpy="0 -0 0" />
        <axis xyz="0 0 1" />
        <parent link="right_upperarm" />
        <child link="right_lowerarm_virtual" />
        <limit effort="77" velocity="19.9" lower="0" upper="2.617991667" />
    </joint>
    <link name="right_lowerarm_virtual" />
    <joint name="right_elbow_Y" type="revolute">
        <origin xyz="0 0 0" rpy="0 -0 0" />
        <axis xyz="0 1 0" />
        <parent link="right_lowerarm_virtual" />
        <child link="right_lowerarm" />
        <limit effort="15" velocity="6.0" lower="-0.349066" upper="3.14159" />
    </joint>
    <link name="right_lowerarm">
        <inertial>
            <mass value="1.28" />
            <origin xyz="0.003 -0.12 0.004" rpy="0 -0 0" />
            <inertia ixx="0.00825" ixy="0.00009" ixz="0.00004" iyy="0.00127" iyz="-0.00067" izz="0.00767" />
        </inertial>
        <visual>
            <origin xyz="-0.0 0.00 -0.00" rpy="0 -0 0" />
            <geometry>
                <mesh filename="meshes/lowerarm_mesh.STL" scale="0.0064 0.0064 0.0064" />
            </geometry>
            <material name="body_color_R" />
        </visual>
        <visual>
	        <origin xyz="-0.0 0.00 -0.00" rpy="0 -0 0" />
            <geometry>
		        <mesh filename="meshes/elbow_mesh.STL" scale="0.0055 0.0055 0.0055" />
            </geometry>
            <material name="body_color_R" />
        </visual>
    </link>
    <joint name="right_wrist_Z" type="revolute">
        <origin xyz="0 -0.287 0" rpy="0 -0 0" />
        <axis xyz="0 0 1" />
        <parent link="right_lowerarm" />
        <child link="right_hand_virtual" />
        <limit effort="100" velocity="25.0" lower="-1.5708" upper="1.5708" />
    </joint>
    <link name="right_hand_virtual" />
    <joint name="right_wrist_X" type="revolute">
        <origin xyz="0 0 0" rpy="0 -0 0" />
        <axis xyz="-1 0 0" />
        <parent link="right_hand_virtual" />
        <child link="right_hand" />
        <limit effort="100" velocity="6.0" lower="-0.785398" upper="0.785398" />
    </joint>
    <link name="right_hand">
        <inertial>
            <mass value="0.45" />
            <origin xyz="0.015 -0.153 0.014" rpy="0 -0 0" />
            <inertia ixx="0.00558" ixy="0.00073" ixz="0.00034" iyy="0.00216" iyz="-0.0006" izz="0.0047" />
        </inertial>
        </link>
    <joint name="right_hip_Z" type="revolute">
        <origin xyz="0.023 -0.1 0.082" rpy="0 -0 0" />
        <axis xyz="0 0 1" />
        <parent link="middle_pelvis" />
        <child link="right_upperleg_virtual" />
        <limit effort="185" velocity="12.0" lower="-1.047196667" upper="3.14159" />
    </joint>
    <link name="right_upperleg_virtual" />
    <joint name="right_hip_X" type="revolute">
        <origin xyz="0 0 0" rpy="0 -0 0" />
        <axis xyz="-1 0 0" />
        <parent link="right_upperleg_virtual" />
        <child link="right_upperleg_virtual_2" />
        <limit effort="120" velocity="6.0" lower="-1.047196667" upper="1.570795" />
    </joint>
    <link name="right_upperleg_virtual_2" />
    <joint name="right_hip_Y" type="revolute">
        <origin xyz="0 0 0" rpy="0 -0 0" />
        <axis xyz="0 1 0" />
        <parent link="right_upperleg_virtual_2" />
        <child link="right_upperleg" />
        <limit effort="60" velocity="6.0" lower="-1.570795" upper="1.047196667" />
    </joint>
    <link name="right_upperleg">
        <inertial>
            <mass value="9.22" />
            <origin xyz="-0.018 -0.188 0.014" rpy="0 -0 0" />
            <inertia ixx="0.1497" ixy="0.00872" ixz="-0.00071" iyy="0.04005" iyz="-0.00872" izz="0.1602" />
        </inertial>
        <visual>
            <origin xyz="-0.0 -0.05 -0.00" rpy="0 -0 0" />
            <geometry>
                <mesh filename="meshes/upperleg_mesh.STL" scale="0.0062 0.0064 0.0069" />
            </geometry>
            <material name="body_color_R" />
        </visual>
    </link>
    <joint name="right_knee_Z" type="revolute">
        <origin xyz="0 -0.439 0" rpy="0 -0 0" />
        <axis xyz="0 0 -1" />
        <parent link="right_upperleg" />
        <child link="right_lowerleg" />
        <limit effort="130" velocity="18.6" lower="0" upper="3.14159" />
    </joint>
    <link name="right_lowerleg">
        <inertial>
            <mass value="3.6" />
            <origin xyz="-0.021 -0.181 0.003" rpy="0 -0 0" />
            <inertia ixx="0.05471" ixy="0.00112" ixz="0.00028" iyy="0.00698" iyz="0.00174" izz="0.05471" />
        </inertial>
        <visual>
            <origin xyz="-0.0 0.00 -0.00" rpy="0 -0 0" />
            <geometry>
                <mesh filename="meshes/lowerleg_mesh.STL" scale="0.0063 0.0066 0.007" />
            </geometry>
            <material name="body_color_R" />
        </visual>
        <visual>
            <origin xyz="-0.0 0.0 -0.0" rpy="0 -0 0" />
            <geometry>
                <mesh filename="meshes/knee_mesh.STL" scale="0.0056 0.0056 0.0056" />
            </geometry>
            <material name="body_color_R" />
        </visual>
    </link>
    <joint name="right_ankle_Z" type="revolute">
        <origin xyz="0 -0.44 0" rpy="0 -0 0" />
        <axis xyz="0 0 1" />
        <parent link="right_lowerleg" />
        <child link="right_foot_virtual" />
        <limit effort="126" velocity="12.7" lower="-1.570795" upper="0.7853975" />
    </joint>
    <link name="right_foot_virtual" />
    <joint name="right_ankle_X" type="revolute">
        <origin xyz="0 0 0" rpy="0 -0 0" />
        <axis xyz="1 0 0" />
        <parent link="right_foot_virtual" />
        <child link="right_foot" />
        <limit effort="20" velocity="6.0" lower="-0.523598333" upper="0.785398" />
    </joint>
    <link name="right_foot">
        <inertial>
            <mass value="0.9" />
            <origin xyz="0.068 -0.027 0.005" rpy="0 -0 0" />
            <inertia ixx="0.00081" ixy="0.00048" ixz="-0.00018" iyy="0.00385" iyz="0.0" izz="0.00364" />
        </inertial>
        <visual>
            <origin xyz="-0.00 -0.00 0.00" rpy="0 0 0" />
            <geometry>
		        <mesh filename="meshes/foot_mesh.STL" scale="0.0067 0.0067 0.0067" />
                
            </geometry>
            <material name="body_color_R" />
        </visual>
    </link>
<link name="mano_right_right_hand_wrist">
    <inertial>
      <origin xyz="0.0 0.0 0.0" rpy="0.0 0.0 0.0" />
      <mass value="0.01" />
      <inertia ixx="0.1" ixy="0.0" ixz="0.0" iyy="0.1" iyz="0.0" izz="0.1" />
    </inertial>
  </link>

  <joint name="mano_right_j_wrist" type="fixed">
    <parent link="mano_right_right_hand_wrist" />
    <child link="mano_right_palm" />
    <origin xyz="0.0 0.0 0.0" rpy="0.0 0.0 0.0" />
  </joint>

  <link name="mano_right_palm">
    <inertial>
      <origin xyz="0.0 0.0 0.0" rpy="0.0 -0.0 0.0" />
      <mass value="0.02" />
      <inertia ixx="1.0" ixy="0.0" ixz="0.0" iyy="1.0" iyz="0.0" izz="1.0" />
    </inertial>
    <visual>
      <geometry>
        <mesh filename="mano_meshes/palm.stl" />
      </geometry>
      <origin xyz="0.0 0.0 0.0" rpy="0.0 -0.0 0.0" />
    </visual>
    <collision name="c_palm">
      <geometry>
        <mesh filename="mano_meshes/palm.stl" />
      </geometry>
      <origin xyz="0.0 0.0 0.0" rpy="0.0 -0.0 0.0" />
    </collision>
  </link>

  <link name="mano_right_index1y">
    <inertial>
      <origin xyz="0.0 0.0 0.0" rpy="0.0 -0.0 0.0" />
      <mass value="0.02" />
      <inertia ixx="1.0" ixy="0.0" ixz="0.0" iyy="1.0" iyz="0.0" izz="1.0" />
    </inertial>
  </link>
  <link name="mano_right_middle1y">
    <inertial>
      <origin xyz="0.0 0.0 0.0" rpy="0.0 -0.0 0.0" />
      <mass value="0.02" />
      <inertia ixx="1.0" ixy="0.0" ixz="0.0" iyy="1.0" iyz="0.0" izz="1.0" />
    </inertial>
  </link>
  <link name="mano_right_pinky1y">
    <inertial>
      <origin xyz="0.0 0.0 0.0" rpy="0.0 -0.0 0.0" />
      <mass value="0.02" />
      <inertia ixx="1.0" ixy="0.0" ixz="0.0" iyy="1.0" iyz="0.0" izz="1.0" />
    </inertial>
  </link>
  <link name="mano_right_ring1y">
    <inertial>
      <origin xyz="0.0 0.0 0.0" rpy="0.0 -0.0 0.0" />
      <mass value="0.02" />
      <inertia ixx="1.0" ixy="0.0" ixz="0.0" iyy="1.0" iyz="0.0" izz="1.0" />
    </inertial>
  </link>
  <link name="mano_right_thumb1y">
    <inertial>
      <origin xyz="0.0 0.0 0.0" rpy="0.0 -0.0 0.0" />
      <mass value="0.02" />
      <inertia ixx="1.0" ixy="0.0" ixz="0.0" iyy="1.0" iyz="0.0" izz="1.0" />
    </inertial>
  </link>

  <link name="mano_right_index1x">
    <inertial>
      <origin xyz="0.0 0.0 0.0" rpy="0.0 -0.0 0.0" />
      <mass value="0.02" />
      <inertia ixx="1.0" ixy="0.0" ixz="0.0" iyy="1.0" iyz="0.0" izz="1.0" />
    </inertial>
    <visual>
      <geometry>
        <mesh filename="mano_meshes/index1x.stl" />
      </geometry>
      <origin xyz="0.0 0.0 0.0" rpy="1.4831328135958037 -1.512034262840266 1.6583093053562068" />
    </visual>
    <collision name="c_index1x">
      <geometry>
        <mesh filename="mano_meshes/index1x.stl" />
      </geometry>
      <origin xyz="0.0 0.0 0.0" rpy="1.4831328135958037 -1.512034262840266 1.6583093053562068" />
    </collision>
  </link>
  <link name="mano_right_index2">
    <inertial>
      <origin xyz="0.0 0.0 0.0" rpy="0.0 -0.0 0.0" />
      <mass value="0.02" />
      <inertia ixx="1.0" ixy="0.0" ixz="0.0" iyy="1.0" iyz="0.0" izz="1.0" />
    </inertial>
    <visual>
      <geometry>
        <mesh filename="mano_meshes/index2.stl" />
      </geometry>
      <origin xyz="0.0 0.0 0.0" rpy="1.4831328135958037 -1.512034262840266 1.6583093053562068" />
    </visual>
    <collision name="c_index2">
      <geometry>
        <mesh filename="mano_meshes/index2.stl" />
      </geometry>
      <origin xyz="0.0 0.0 0.0" rpy="1.4831328135958037 -1.512034262840266 1.6583093053562068" />
    </collision>
  </link>
  <link name="mano_right_index3">
    <inertial>
      <origin xyz="0.0 0.0 0.0" rpy="0.0 -0.0 0.0" />
      <mass value="0.02" />
      <inertia ixx="1.0" ixy="0.0" ixz="0.0" iyy="1.0" iyz="0.0" izz="1.0" />
    </inertial>
    <visual>
      <geometry>
        <mesh filename="mano_meshes/index3.stl" />
      </geometry>
      <origin xyz="0.0 0.0 0.0" rpy="1.4831328135958037 -1.512034262840266 1.6583093053562068" />
    </visual>
    <collision name="c_index3">
      <geometry>
        <mesh filename="mano_meshes/index3.stl" />
      </geometry>
      <origin xyz="0.0 0.0 0.0" rpy="1.4831328135958037 -1.512034262840266 1.6583093053562068" />
    </collision>
  </link>
  <link name="mano_right_middle1x">
    <inertial>
      <origin xyz="0.0 0.0 0.0" rpy="0.0 -0.0 0.0" />
      <mass value="0.02" />
      <inertia ixx="1.0" ixy="0.0" ixz="0.0" iyy="1.0" iyz="0.0" izz="1.0" />
    </inertial>
    <visual>
      <geometry>
        <mesh filename="mano_meshes/middle1x.stl" />
      </geometry>
      <origin xyz="0.0 0.0 0.0" rpy="0.3073692753779058 -1.3920421760802733 2.8108489113038133" />
    </visual>
    <collision name="c_middle1x">
      <geometry>
        <mesh filename="mano_meshes/middle1x.stl" />
      </geometry>
      <origin xyz="0.0 0.0 0.0" rpy="0.3073692753779058 -1.3920421760802733 2.8108489113038133" />
    </collision>
  </link>
  <link name="mano_right_middle2">
    <inertial>
      <origin xyz="0.0 0.0 0.0" rpy="0.0 -0.0 0.0" />
      <mass value="0.02" />
      <inertia ixx="1.0" ixy="0.0" ixz="0.0" iyy="1.0" iyz="0.0" izz="1.0" />
    </inertial>
    <visual>
      <geometry>
        <mesh filename="mano_meshes/middle2.stl" />
      </geometry>
      <origin xyz="0.0 0.0 0.0" rpy="0.3073692753779058 -1.3920421760802733 2.8108489113038133" />
    </visual>
    <collision name="c_middle2">
      <geometry>
        <mesh filename="mano_meshes/middle2.stl" />
      </geometry>
      <origin xyz="0.0 0.0 0.0" rpy="0.3073692753779058 -1.3920421760802733 2.8108489113038133" />
    </collision>
  </link>
  <link name="mano_right_middle3">
    <inertial>
      <origin xyz="0.0 0.0 0.0" rpy="0.0 -0.0 0.0" />
      <mass value="0.02" />
      <inertia ixx="1.0" ixy="0.0" ixz="0.0" iyy="1.0" iyz="0.0" izz="1.0" />
    </inertial>
    <visual>
      <geometry>
        <mesh filename="mano_meshes/middle3.stl" />
      </geometry>
      <origin xyz="0.0 0.0 0.0" rpy="0.3073692753779058 -1.3920421760802733 2.8108489113038133" />
    </visual>
    <collision name="c_middle3">
      <geometry>
        <mesh filename="mano_meshes/middle3.stl" />
      </geometry>
      <origin xyz="0.0 0.0 0.0" rpy="0.3073692753779058 -1.3920421760802733 2.8108489113038133" />
    </collision>
  </link>
  <link name="mano_right_pinky1x">
    <inertial>
      <origin xyz="0.0 0.0 0.0" rpy="0.0 -0.0 0.0" />
      <mass value="0.02" />
      <inertia ixx="1.0" ixy="0.0" ixz="0.0" iyy="1.0" iyz="0.0" izz="1.0" />
    </inertial>
    <visual>
      <geometry>
        <mesh filename="mano_meshes/pinky1x.stl" />
      </geometry>
      <origin xyz="0.0 0.0 0.0" rpy="0.06679576746850734 -0.992584043476312 -2.9162705580617776" />
    </visual>
    <collision name="c_pinky1x">
      <geometry>
        <mesh filename="mano_meshes/pinky1x.stl" />
      </geometry>
      <origin xyz="0.0 0.0 0.0" rpy="0.06679576746850734 -0.992584043476312 -2.9162705580617776" />
    </collision>
  </link>
  <link name="mano_right_pinky2">
    <inertial>
      <origin xyz="0.0 0.0 0.0" rpy="0.0 -0.0 0.0" />
      <mass value="0.02" />
      <inertia ixx="1.0" ixy="0.0" ixz="0.0" iyy="1.0" iyz="0.0" izz="1.0" />
    </inertial>
    <visual>
      <geometry>
        <mesh filename="mano_meshes/pinky2.stl" />
      </geometry>
      <origin xyz="0.0 0.0 0.0" rpy="0.06679576746850734 -0.992584043476312 -2.9162705580617776" />
    </visual>
    <collision name="c_pinky2">
      <geometry>
        <mesh filename="mano_meshes/pinky2.stl" />
      </geometry>
      <origin xyz="0.0 0.0 0.0" rpy="0.06679576746850734 -0.992584043476312 -2.9162705580617776" />
    </collision>
  </link>
  <link name="mano_right_pinky3">
    <inertial>
      <origin xyz="0.0 0.0 0.0" rpy="0.0 -0.0 0.0" />
      <mass value="0.02" />
      <inertia ixx="1.0" ixy="0.0" ixz="0.0" iyy="1.0" iyz="0.0" izz="1.0" />
    </inertial>
    <visual>
      <geometry>
        <mesh filename="mano_meshes/pinky3.stl" />
      </geometry>
      <origin xyz="0.0 0.0 0.0" rpy="0.06679576746850734 -0.992584043476312 -2.9162705580617776" />
    </visual>
    <collision name="c_pinky3">
      <geometry>
        <mesh filename="mano_meshes/pinky3.stl" />
      </geometry>
      <origin xyz="0.0 0.0 0.0" rpy="0.06679576746850734 -0.992584043476312 -2.9162705580617776" />
    </collision>
  </link>
  <link name="mano_right_ring1x">
    <inertial>
      <origin xyz="0.0 0.0 0.0" rpy="0.0 -0.0 0.0" />
      <mass value="0.02" />
      <inertia ixx="1.0" ixy="0.0" ixz="0.0" iyy="1.0" iyz="0.0" izz="1.0" />
    </inertial>
    <visual>
      <geometry>
        <mesh filename="mano_meshes/ring1x.stl" />
      </geometry>
      <origin xyz="0.0 0.0 0.0" rpy="0.2176336888802252 -1.2498852725580183 3.0420942217754825" />
    </visual>
    <collision name="c_ring1x">
      <geometry>
        <mesh filename="mano_meshes/ring1x.stl" />
      </geometry>
      <origin xyz="0.0 0.0 0.0" rpy="0.2176336888802252 -1.2498852725580183 3.0420942217754825" />
    </collision>
  </link>
  <link name="mano_right_ring2">
    <inertial>
      <origin xyz="0.0 0.0 0.0" rpy="0.0 -0.0 0.0" />
      <mass value="0.02" />
      <inertia ixx="1.0" ixy="0.0" ixz="0.0" iyy="1.0" iyz="0.0" izz="1.0" />
    </inertial>
    <visual>
      <geometry>
        <mesh filename="mano_meshes/ring2.stl" />
      </geometry>
      <origin xyz="0.0 0.0 0.0" rpy="0.2176336888802252 -1.2498852725580183 3.0420942217754825" />
    </visual>
    <collision name="c_ring2">
      <geometry>
        <mesh filename="mano_meshes/ring2.stl" />
      </geometry>
      <origin xyz="0.0 0.0 0.0" rpy="0.2176336888802252 -1.2498852725580183 3.0420942217754825" />
    </collision>
  </link>
  <link name="mano_right_ring3">
    <inertial>
      <origin xyz="0.0 0.0 0.0" rpy="0.0 -0.0 0.0" />
      <mass value="0.02" />
      <inertia ixx="1.0" ixy="0.0" ixz="0.0" iyy="1.0" iyz="0.0" izz="1.0" />
    </inertial>
    <visual>
      <geometry>
        <mesh filename="mano_meshes/ring3.stl" />
      </geometry>
      <origin xyz="0.0 0.0 0.0" rpy="0.2176336888802252 -1.2498852725580183 3.0420942217754825" />
    </visual>
    <collision name="c_ring3">
      <geometry>
        <mesh filename="mano_meshes/ring3.stl" />
      </geometry>
      <origin xyz="0.0 0.0 0.0" rpy="0.2176336888802252 -1.2498852725580183 3.0420942217754825" />
    </collision>
  </link>
  <link name="mano_right_thumb1z">
    <inertial>
      <origin xyz="0.0 0.0 0.0" rpy="0.0 -0.0 0.0" />
      <mass value="0.02" />
      <inertia ixx="1.0" ixy="0.0" ixz="0.0" iyy="1.0" iyz="0.0" izz="1.0" />
    </inertial>
    <visual>
      <geometry>
        <mesh filename="mano_meshes/thumb1z.stl" />
      </geometry>
      <origin xyz="0.0 0.0 0.0" rpy="1.4810257760657597 -0.15224451823600868 1.6636707290524053" />
    </visual>
    <collision name="c_thumb1z">
      <geometry>
        <mesh filename="mano_meshes/thumb1z.stl" />
      </geometry>
      <origin xyz="0.0 0.0 0.0" rpy="1.4810257760657597 -0.15224451823600868 1.6636707290524053" />
    </collision>
  </link>
  <link name="mano_right_thumb2">
    <inertial>
      <origin xyz="0.0 0.0 0.0" rpy="0.0 -0.0 0.0" />
      <mass value="0.02" />
      <inertia ixx="1.0" ixy="0.0" ixz="0.0" iyy="1.0" iyz="0.0" izz="1.0" />
    </inertial>
    <visual>
      <geometry>
        <mesh filename="mano_meshes/thumb2.stl" />
      </geometry>
      <origin xyz="0.0 0.0 0.0" rpy="2.78364154749573 -0.9614434923439676 -0.6974669503609245" />
    </visual>
    <collision name="c_thumb2">
      <geometry>
        <mesh filename="mano_meshes/thumb2.stl" />
      </geometry>
      <origin xyz="0.0 0.0 0.0" rpy="2.78364154749573 -0.9614434923439676 -0.6974669503609245" />
    </collision>
  </link>
  <link name="mano_right_thumb3">
    <inertial>
      <origin xyz="0.0 0.0 0.0" rpy="0.0 -0.0 0.0" />
      <mass value="0.02" />
      <inertia ixx="1.0" ixy="0.0" ixz="0.0" iyy="1.0" iyz="0.0" izz="1.0" />
    </inertial>
    <visual>
      <geometry>
        <mesh filename="mano_meshes/thumb3.stl" />
      </geometry>
      <origin xyz="0.0 0.0 0.0" rpy="2.78364154749573 -0.9614434923439676 -0.6974669503609245" />
    </visual>
    <collision name="c_thumb3">
      <geometry>
        <mesh filename="mano_meshes/thumb3.stl" />
      </geometry>
      <origin xyz="0.0 0.0 0.0" rpy="2.78364154749573 -0.9614434923439676 -0.6974669503609245" />
    </collision>
  </link>

  <joint name="mano_right_j_index1y" type="revolute">
    <limit effort="100.0" velocity="100.0" lower="-0.3490658503988659" upper="0.3490658503988659" />
    <parent link="mano_right_palm" />
    <child link="mano_right_index1y" />
    <axis xyz="0. 1. 0." />
    <origin xyz="-0.08809724664019486 -0.0052003570684035555 0.02068598903709729" rpy="0.0 -1.5656545707276812 -3.0830557190223242" />
  </joint>
  <joint name="mano_right_j_index1x" type="revolute">
    <limit effort="100.0" velocity="100.0" lower="-0.17453292519943295" upper="1.5707963267948966" />
    <parent link="mano_right_index1y" />
    <child link="mano_right_index1x" />
    <axis xyz="1. 0. 0." />
    <origin xyz="0.0 0.0 0.0" rpy="0.0 -0.0 0.0" />
  </joint>
  <joint name="mano_right_j_index2" type="revolute">
    <limit effort="100.0" velocity="100.0" lower="0.0" upper="1.7453292519943295" />
    <parent link="mano_right_index1x" />
    <child link="mano_right_index2" />
    <axis xyz="1. 0. 0." />
    <origin xyz="0.0023835711672753985 -0.005914318759078097 -0.03237654210665609" rpy="5.985723906621881e-19 -6.835640390420038e-19 -6.486977305262269e-21" />
  </joint>
  <joint name="mano_right_j_index3" type="revolute">
    <limit effort="100.0" velocity="100.0" lower="0.0" upper="1.7453292519943295" />
    <parent link="mano_right_index2" />
    <child link="mano_right_index3" />
    <axis xyz="1. 0. 0." />
    <origin xyz="-2.1969386803155346e-21 1.0054815357582629e-19 -0.022194219361846432" rpy="5.985723906621881e-19 -6.835640390420038e-19 -6.486977305262269e-21" />
  </joint>
  <joint name="mano_right_j_middle1y" type="revolute">
    <limit effort="100.0" velocity="100.0" lower="-0.5235987755982988" upper="0.3490658503988659" />
    <parent link="mano_right_palm" />
    <child link="mano_right_middle1y" />
    <axis xyz="0. 1. 0." />
    <origin xyz="-0.09466044139183748 -0.0014789633509431728 -0.0033575408143170205" rpy="-0.10838501782646781 -1.399488824140411 -2.9769988584801235" />
  </joint>
  <joint name="mano_right_j_middle1x" type="revolute">
    <limit effort="100.0" velocity="100.0" lower="-0.17453292519943295" upper="1.5707963267948966" />
    <parent link="mano_right_middle1y" />
    <child link="mano_right_middle1x" />
    <axis xyz="1. 0. 0." />
    <origin xyz="0.0 0.0 0.0" rpy="0.0 -0.0 0.0" />
  </joint>
  <joint name="mano_right_j_middle2" type="revolute">
    <limit effort="100.0" velocity="100.0" lower="0.0" upper="1.7453292519943295" />
    <parent link="mano_right_middle1x" />
    <child link="mano_right_middle2" />
    <axis xyz="1. 0. 0." />
    <origin xyz="-0.0003207158897834246 -0.003555264565700651 -0.031533781277300055" rpy="-7.187502047679508e-19 1.1776617696394585e-17 -1.1633025402259818e-18" />
  </joint>
  <joint name="mano_right_j_middle3" type="revolute">
    <limit effort="100.0" velocity="100.0" lower="0.0" upper="1.7453292519943295" />
    <parent link="mano_right_middle2" />
    <child link="mano_right_middle3" />
    <axis xyz="1. 0. 0." />
    <origin xyz="-5.609489609703704e-20 -7.277896970840872e-20 -0.023275512883098835" rpy="-7.187502047679508e-19 1.1776617696394585e-17 -1.1633025402259818e-18" />
  </joint>
  <joint name="mano_right_j_pinky1y" type="revolute">
    <limit effort="100.0" velocity="100.0" lower="-0.6981317007977318" upper="0.3490658503988659" />
    <parent link="mano_right_palm" />
    <child link="mano_right_pinky1y" />
    <axis xyz="0. 1. 0." />
    <origin xyz="-0.0687869720598841 -0.00994032882044861 -0.04320934200328496" rpy="0.4325014617037457 -0.9265283135189503 2.661490603166245" />
  </joint>
  <joint name="mano_right_j_pinky1x" type="revolute">
    <limit effort="100.0" velocity="100.0" lower="-0.17453292519943295" upper="1.5707963267948966" />
    <parent link="mano_right_pinky1y" />
    <child link="mano_right_pinky1x" />
    <axis xyz="1. 0. 0." />
    <origin xyz="0.0 0.0 0.0" rpy="0.0 -0.0 0.0" />
  </joint>
  <joint name="mano_right_j_pinky2" type="revolute">
    <limit effort="100.0" velocity="100.0" lower="0.0" upper="1.7453292519943295" />
    <parent link="mano_right_pinky1x" />
    <child link="mano_right_pinky2" />
    <axis xyz="1. 0. 0." />
    <origin xyz="-0.0009123243154268479 -0.0011282837702486126 -0.021062001859487044" rpy="-2.484200750483751e-17 -7.081513656750915e-17 -2.6504116429611938e-17" />
  </joint>
  <joint name="mano_right_j_pinky3" type="revolute">
    <limit effort="100.0" velocity="100.0" lower="0.0" upper="1.7453292519943295" />
    <parent link="mano_right_pinky2" />
    <child link="mano_right_pinky3" />
    <axis xyz="1. 0. 0." />
    <origin xyz="-1.8952144180532274e-18 2.2152413969868993e-19 -0.01894688789602988" rpy="-2.484200750483751e-17 -7.081513656750915e-17 -2.6504116429611938e-17" />
  </joint>
  <joint name="mano_right_j_ring1y" type="revolute">
    <limit effort="100.0" velocity="100.0" lower="-0.5235987755982988" upper="0.3490658503988659" />
    <parent link="mano_right_palm" />
    <child link="mano_right_ring1y" />
    <axis xyz="0. 1. 0." />
    <origin xyz="-0.08173555442881024 -0.003957421152865242 -0.026673193033088197" rpy="0.3794310720777505 -1.2328253203111788 2.8133517240851353" />
  </joint>
  <joint name="mano_right_j_ring1x" type="revolute">
    <limit effort="100.0" velocity="100.0" lower="-0.17453292519943295" upper="1.5707963267948966" />
    <parent link="mano_right_ring1y" />
    <child link="mano_right_ring1x" />
    <axis xyz="1. 0. 0." />
    <origin xyz="0.0 0.0 0.0" rpy="0.0 -0.0 0.0" />
  </joint>
  <joint name="mano_right_j_ring2" type="revolute">
    <limit effort="100.0" velocity="100.0" lower="0.0" upper="1.7453292519943295" />
    <parent link="mano_right_ring1x" />
    <child link="mano_right_ring2" />
    <axis xyz="1. 0. 0." />
    <origin xyz="0.00429786987999866 -0.003563675567715413 -0.028298309378744307" rpy="-6.026737690030247e-18 -3.508963367964836e-17 -1.7519875374215658e-17" />
  </joint>
  <joint name="mano_right_j_ring3" type="revolute">
    <limit effort="100.0" velocity="100.0" lower="0.0" upper="1.7453292519943295" />
    <parent link="mano_right_ring2" />
    <child link="mano_right_ring3" />
    <axis xyz="1. 0. 0." />
    <origin xyz="-7.238679066856496e-20 2.4155957590579026e-19 -0.02478587029620925" rpy="-6.026737690030247e-18 -3.508963367964836e-17 -1.7519875374215658e-17" />
  </joint>
  <joint name="mano_right_j_thumb1y" type="revolute">
    <limit effort="100.0" velocity="100.0" lower="-0.17453292519943295" upper="2.6179938779914944" />
    <parent link="mano_right_palm" />
    <child link="mano_right_thumb1y" />
    <axis xyz="0. 1. 0." />
    <origin xyz="-0.024089706802642025 -0.015522334541875703 0.025812847288082738" rpy="0.7270385771615225 -1.451914435932513 -2.4542043209348736" />
  </joint>
  <joint name="mano_right_j_thumb1z" type="revolute">
    <limit effort="100.0" velocity="100.0" lower="-0.6981317007977318" upper="0.6981317007977318" />
    <parent link="mano_right_thumb1y" />
    <child link="mano_right_thumb1z" />
    <axis xyz="0. 0. 1." />
    <origin xyz="0.0 0.0 0.0" rpy="0.0 -0.0 0.0" />
  </joint>
  <joint name="mano_right_j_thumb2" type="revolute">
    <limit effort="100.0" velocity="100.0" lower="0.0" upper="1.7453292519943295" />
    <parent link="mano_right_thumb1z" />
    <child link="mano_right_thumb2" />
    <axis xyz="1. 0. 0." />
    <origin xyz="0.02526494873869172 -0.017595730026252792 1.0660017461924156e-19" rpy="-1.1705944339598562 0.7898458524685564 0.9959904350807831" />
  </joint>
  <joint name="mano_right_j_thumb3" type="revolute">
    <limit effort="100.0" velocity="100.0" lower="0.0" upper="1.7453292519943295" />
    <parent link="mano_right_thumb2" />
    <child link="mano_right_thumb3" />
    <axis xyz="1. 0. 0." />
    <origin xyz="1.6439906908155651e-19 1.0686676358921293e-18 -0.027094189966248017" rpy="-3.586194595879372e-17 2.2299700610673483e-17 5.828722753684352e-18" />
  </joint>
<joint name="human_to_right_mano" type="fixed"><origin xyz="0 0 0" rpy="1.5708 0 1.5708" /><parent link="right_hand" /><child link="mano_right_right_hand_wrist" /></joint><link name="mano_left_left_hand_wrist">
    <inertial>
      <origin xyz="0.0 0.0 0.0" rpy="0.0 0.0 0.0" />
      <mass value="0.01" />
      <inertia ixx="0.1" ixy="0.0" ixz="0.0" iyy="0.1" iyz="0.0" izz="0.1" />
    </inertial>
  </link>

  <joint name="mano_left_j_wrist" type="fixed">
    <parent link="mano_left_left_hand_wrist" />
    <child link="mano_left_palm" />
    <origin xyz="0.0 0.0 0.0" rpy="0.0 0.0 0.0" />
  </joint>

  <link name="mano_left_palm">
    <inertial>
      <origin xyz="0.0 0.0 0.0" rpy="0.0 0.0 0.0" />
      <mass value="0.02" />
      <inertia ixx="1.0" ixy="0.0" ixz="0.0" iyy="1.0" iyz="0.0" izz="1.0" />
    </inertial>
    <visual>
      <geometry>
        <mesh filename="mano_meshes/palm.stl" scale="1 1 -1" />
      </geometry>
      <origin xyz="0.0 0.0 0.0" rpy="0.0 0.0 0.0" />
    </visual>
    <collision name="c_palm">
      <geometry>
        <mesh filename="mano_meshes/palm.stl" scale="1 1 -1" />
      </geometry>
      <origin xyz="0.0 0.0 0.0" rpy="0.0 0.0 0.0" />
    </collision>
  </link>

  <link name="mano_left_index1y">
    <inertial>
      <origin xyz="0.0 0.0 0.0" rpy="0.0 0.0 0.0" />
      <mass value="0.02" />
      <inertia ixx="1.0" ixy="0.0" ixz="0.0" iyy="1.0" iyz="0.0" izz="1.0" />
    </inertial>
  </link>
  <link name="mano_left_middle1y">
    <inertial>
      <origin xyz="0.0 0.0 0.0" rpy="0.0 0.0 0.0" />
      <mass value="0.02" />
      <inertia ixx="1.0" ixy="0.0" ixz="0.0" iyy="1.0" iyz="0.0" izz="1.0" />
    </inertial>
  </link>
  <link name="mano_left_pinky1y">
    <inertial>
      <origin xyz="0.0 0.0 0.0" rpy="0.0 0.0 0.0" />
      <mass value="0.02" />
      <inertia ixx="1.0" ixy="0.0" ixz="0.0" iyy="1.0" iyz="0.0" izz="1.0" />
    </inertial>
  </link>
  <link name="mano_left_ring1y">
    <inertial>
      <origin xyz="0.0 0.0 0.0" rpy="0.0 0.0 0.0" />
      <mass value="0.02" />
      <inertia ixx="1.0" ixy="0.0" ixz="0.0" iyy="1.0" iyz="0.0" izz="1.0" />
    </inertial>
  </link>
  <link name="mano_left_thumb1y">
    <inertial>
      <origin xyz="0.0 0.0 0.0" rpy="0.0 0.0 0.0" />
      <mass value="0.02" />
      <inertia ixx="1.0" ixy="0.0" ixz="0.0" iyy="1.0" iyz="0.0" izz="1.0" />
    </inertial>
  </link>

  <link name="mano_left_index1x">
    <inertial>
      <origin xyz="0.0 0.0 0.0" rpy="0.0 0.0 0.0" />
      <mass value="0.02" />
      <inertia ixx="1.0" ixy="0.0" ixz="0.0" iyy="1.0" iyz="0.0" izz="1.0" />
    </inertial>
    <visual>
      <geometry>
        <mesh filename="mano_meshes/index1x.stl" scale="1 1 -1" />
      </geometry>
      <origin xyz="0.0 0.0 0.0" rpy="-1.4831328135958037 1.512034262840266 1.6583093053562068" />
    </visual>
    <collision name="c_index1x">
      <geometry>
        <mesh filename="mano_meshes/index1x.stl" scale="1 1 -1" />
      </geometry>
      <origin xyz="0.0 0.0 0.0" rpy="-1.4831328135958037 1.512034262840266 1.6583093053562068" />
    </collision>
  </link>
  <link name="mano_left_index2">
    <inertial>
      <origin xyz="0.0 0.0 0.0" rpy="0.0 0.0 0.0" />
      <mass value="0.02" />
      <inertia ixx="1.0" ixy="0.0" ixz="0.0" iyy="1.0" iyz="0.0" izz="1.0" />
    </inertial>
    <visual>
      <geometry>
        <mesh filename="mano_meshes/index2.stl" scale="1 1 -1" />
      </geometry>
      <origin xyz="0.0 0.0 0.0" rpy="-1.4831328135958037 1.512034262840266 1.6583093053562068" />
    </visual>
    <collision name="c_index2">
      <geometry>
        <mesh filename="mano_meshes/index2.stl" scale="1 1 -1" />
      </geometry>
      <origin xyz="0.0 0.0 0.0" rpy="-1.4831328135958037 1.512034262840266 1.6583093053562068" />
    </collision>
  </link>
  <link name="mano_left_index3">
    <inertial>
      <origin xyz="0.0 0.0 0.0" rpy="0.0 0.0 0.0" />
      <mass value="0.02" />
      <inertia ixx="1.0" ixy="0.0" ixz="0.0" iyy="1.0" iyz="0.0" izz="1.0" />
    </inertial>
    <visual>
      <geometry>
        <mesh filename="mano_meshes/index3.stl" scale="1 1 -1" />
      </geometry>
      <origin xyz="0.0 0.0 0.0" rpy="-1.4831328135958037 1.512034262840266 1.6583093053562068" />
    </visual>
    <collision name="c_index3">
      <geometry>
        <mesh filename="mano_meshes/index3.stl" scale="1 1 -1" />
      </geometry>
      <origin xyz="0.0 0.0 0.0" rpy="-1.4831328135958037 1.512034262840266 1.6583093053562068" />
    </collision>
  </link>
  <link name="mano_left_middle1x">
    <inertial>
      <origin xyz="0.0 0.0 0.0" rpy="0.0 0.0 0.0" />
      <mass value="0.02" />
      <inertia ixx="1.0" ixy="0.0" ixz="0.0" iyy="1.0" iyz="0.0" izz="1.0" />
    </inertial>
    <visual>
      <geometry>
        <mesh filename="mano_meshes/middle1x.stl" scale="1 1 -1" />
      </geometry>
      <origin xyz="0.0 0.0 0.0" rpy="-0.3073692753779058 1.3920421760802733 2.8108489113038133" />
    </visual>
    <collision name="c_middle1x">
      <geometry>
        <mesh filename="mano_meshes/middle1x.stl" scale="1 1 -1" />
      </geometry>
      <origin xyz="0.0 0.0 0.0" rpy="-0.3073692753779058 1.3920421760802733 2.8108489113038133" />
    </collision>
  </link>
  <link name="mano_left_middle2">
    <inertial>
      <origin xyz="0.0 0.0 0.0" rpy="0.0 0.0 0.0" />
      <mass value="0.02" />
      <inertia ixx="1.0" ixy="0.0" ixz="0.0" iyy="1.0" iyz="0.0" izz="1.0" />
    </inertial>
    <visual>
      <geometry>
        <mesh filename="mano_meshes/middle2.stl" scale="1 1 -1" />
      </geometry>
      <origin xyz="0.0 0.0 0.0" rpy="-0.3073692753779058 1.3920421760802733 2.8108489113038133" />
    </visual>
    <collision name="c_middle2">
      <geometry>
        <mesh filename="mano_meshes/middle2.stl" scale="1 1 -1" />
      </geometry>
      <origin xyz="0.0 0.0 0.0" rpy="-0.3073692753779058 1.3920421760802733 2.8108489113038133" />
    </collision>
  </link>
  <link name="mano_left_middle3">
    <inertial>
      <origin xyz="0.0 0.0 0.0" rpy="0.0 0.0 0.0" />
      <mass value="0.02" />
      <inertia ixx="1.0" ixy="0.0" ixz="0.0" iyy="1.0" iyz="0.0" izz="1.0" />
    </inertial>
    <visual>
      <geometry>
        <mesh filename="mano_meshes/middle3.stl" scale="1 1 -1" />
      </geometry>
      <origin xyz="0.0 0.0 0.0" rpy="-0.3073692753779058 1.3920421760802733 2.8108489113038133" />
    </visual>
    <collision name="c_middle3">
      <geometry>
        <mesh filename="mano_meshes/middle3.stl" scale="1 1 -1" />
      </geometry>
      <origin xyz="0.0 0.0 0.0" rpy="-0.3073692753779058 1.3920421760802733 2.8108489113038133" />
    </collision>
  </link>
  <link name="mano_left_pinky1x">
    <inertial>
      <origin xyz="0.0 0.0 0.0" rpy="0.0 0.0 0.0" />
      <mass value="0.02" />
      <inertia ixx="1.0" ixy="0.0" ixz="0.0" iyy="1.0" iyz="0.0" izz="1.0" />
    </inertial>
    <visual>
      <geometry>
        <mesh filename="mano_meshes/pinky1x.stl" scale="1 1 -1" />
      </geometry>
      <origin xyz="0.0 0.0 0.0" rpy="-0.06679576746850734 0.992584043476312 -2.9162705580617776" />
    </visual>
    <collision name="c_pinky1x">
      <geometry>
        <mesh filename="mano_meshes/pinky1x.stl" scale="1 1 -1" />
      </geometry>
      <origin xyz="0.0 0.0 0.0" rpy="-0.06679576746850734 0.992584043476312 -2.9162705580617776" />
    </collision>
  </link>
  <link name="mano_left_pinky2">
    <inertial>
      <origin xyz="0.0 0.0 0.0" rpy="0.0 0.0 0.0" />
      <mass value="0.02" />
      <inertia ixx="1.0" ixy="0.0" ixz="0.0" iyy="1.0" iyz="0.0" izz="1.0" />
    </inertial>
    <visual>
      <geometry>
        <mesh filename="mano_meshes/pinky2.stl" scale="1 1 -1" />
      </geometry>
      <origin xyz="0.0 0.0 0.0" rpy="-0.06679576746850734 0.992584043476312 -2.9162705580617776" />
    </visual>
    <collision name="c_pinky2">
      <geometry>
        <mesh filename="mano_meshes/pinky2.stl" scale="1 1 -1" />
      </geometry>
      <origin xyz="0.0 0.0 0.0" rpy="-0.06679576746850734 0.992584043476312 -2.9162705580617776" />
    </collision>
  </link>
  <link name="mano_left_pinky3">
    <inertial>
      <origin xyz="0.0 0.0 0.0" rpy="0.0 0.0 0.0" />
      <mass value="0.02" />
      <inertia ixx="1.0" ixy="0.0" ixz="0.0" iyy="1.0" iyz="0.0" izz="1.0" />
    </inertial>
    <visual>
      <geometry>
        <mesh filename="mano_meshes/pinky3.stl" scale="1 1 -1" />
      </geometry>
      <origin xyz="0.0 0.0 0.0" rpy="-0.06679576746850734 0.992584043476312 -2.9162705580617776" />
    </visual>
    <collision name="c_pinky3">
      <geometry>
        <mesh filename="mano_meshes/pinky3.stl" scale="1 1 -1" />
      </geometry>
      <origin xyz="0.0 0.0 0.0" rpy="-0.06679576746850734 0.992584043476312 -2.9162705580617776" />
    </collision>
  </link>
  <link name="mano_left_ring1x">
    <inertial>
      <origin xyz="0.0 0.0 0.0" rpy="0.0 0.0 0.0" />
      <mass value="0.02" />
      <inertia ixx="1.0" ixy="0.0" ixz="0.0" iyy="1.0" iyz="0.0" izz="1.0" />
    </inertial>
    <visual>
      <geometry>
        <mesh filename="mano_meshes/ring1x.stl" scale="1 1 -1" />
      </geometry>
      <origin xyz="0.0 0.0 0.0" rpy="-0.2176336888802252 1.2498852725580183 3.0420942217754825" />
    </visual>
    <collision name="c_ring1x">
      <geometry>
        <mesh filename="mano_meshes/ring1x.stl" scale="1 1 -1" />
      </geometry>
      <origin xyz="0.0 0.0 0.0" rpy="-0.2176336888802252 1.2498852725580183 3.0420942217754825" />
    </collision>
  </link>
  <link name="mano_left_ring2">
    <inertial>
      <origin xyz="0.0 0.0 0.0" rpy="0.0 0.0 0.0" />
      <mass value="0.02" />
      <inertia ixx="1.0" ixy="0.0" ixz="0.0" iyy="1.0" iyz="0.0" izz="1.0" />
    </inertial>
    <visual>
      <geometry>
        <mesh filename="mano_meshes/ring2.stl" scale="1 1 -1" />
      </geometry>
      <origin xyz="0.0 0.0 0.0" rpy="-0.2176336888802252 1.2498852725580183 3.0420942217754825" />
    </visual>
    <collision name="c_ring2">
      <geometry>
        <mesh filename="mano_meshes/ring2.stl" scale="1 1 -1" />
      </geometry>
      <origin xyz="0.0 0.0 0.0" rpy="-0.2176336888802252 1.2498852725580183 3.0420942217754825" />
    </collision>
  </link>
  <link name="mano_left_ring3">
    <inertial>
      <origin xyz="0.0 0.0 0.0" rpy="0.0 0.0 0.0" />
      <mass value="0.02" />
      <inertia ixx="1.0" ixy="0.0" ixz="0.0" iyy="1.0" iyz="0.0" izz="1.0" />
    </inertial>
    <visual>
      <geometry>
        <mesh filename="mano_meshes/ring3.stl" scale="1 1 -1" />
      </geometry>
      <origin xyz="0.0 0.0 0.0" rpy="-0.2176336888802252 1.2498852725580183 3.0420942217754825" />
    </visual>
    <collision name="c_ring3">
      <geometry>
        <mesh filename="mano_meshes/ring3.stl" scale="1 1 -1" />
      </geometry>
      <origin xyz="0.0 0.0 0.0" rpy="-0.2176336888802252 1.2498852725580183 3.0420942217754825" />
    </collision>
  </link>
  <link name="mano_left_thumb1z">
    <inertial>
      <origin xyz="0.0 0.0 0.0" rpy="0.0 0.0 0.0" />
      <mass value="0.02" />
      <inertia ixx="1.0" ixy="0.0" ixz="0.0" iyy="1.0" iyz="0.0" izz="1.0" />
    </inertial>
    <visual>
      <geometry>
        <mesh filename="mano_meshes/thumb1z.stl" scale="1 1 -1" />
      </geometry>
      <origin xyz="0.0 0.0 0.0" rpy="-1.4810257760657597 0.15224451823600868 1.6636707290524053" />
    </visual>
    <collision name="c_thumb1z">
      <geometry>
        <mesh filename="mano_meshes/thumb1z.stl" scale="1 1 -1" />
      </geometry>
      <origin xyz="0.0 0.0 0.0" rpy="-1.4810257760657597 0.15224451823600868 1.6636707290524053" />
    </collision>
  </link>
  <link name="mano_left_thumb2">
    <inertial>
      <origin xyz="0.0 0.0 0.0" rpy="0.0 0.0 0.0" />
      <mass value="0.02" />
      <inertia ixx="1.0" ixy="0.0" ixz="0.0" iyy="1.0" iyz="0.0" izz="1.0" />
    </inertial>
    <visual>
      <geometry>
        <mesh filename="mano_meshes/thumb2.stl" scale="1 1 -1" />
      </geometry>
      <origin xyz="0.0 0.0 0.0" rpy="-2.78364154749573 0.9614434923439676 -0.6974669503609245" />
    </visual>
    <collision name="c_thumb2">
      <geometry>
        <mesh filename="mano_meshes/thumb2.stl" scale="1 1 -1" />
      </geometry>
      <origin xyz="0.0 0.0 0.0" rpy="-2.78364154749573 0.9614434923439676 -0.6974669503609245" />
    </collision>
  </link>
  <link name="mano_left_thumb3">
    <inertial>
      <origin xyz="0.0 0.0 0.0" rpy="0.0 0.0 0.0" />
      <mass value="0.02" />
      <inertia ixx="1.0" ixy="0.0" ixz="0.0" iyy="1.0" iyz="0.0" izz="1.0" />
    </inertial>
    <visual>
      <geometry>
        <mesh filename="mano_meshes/thumb3.stl" scale="1 1 -1" />
      </geometry>
      <origin xyz="0.0 0.0 0.0" rpy="-2.78364154749573 0.9614434923439676 -0.6974669503609245" />
    </visual>
    <collision name="c_thumb3">
      <geometry>
        <mesh filename="mano_meshes/thumb3.stl" scale="1 1 -1" />
      </geometry>
      <origin xyz="0.0 0.0 0.0" rpy="-2.78364154749573 0.9614434923439676 -0.6974669503609245" />
    </collision>
  </link>

  <joint name="mano_left_j_index1y" type="revolute">
    <limit effort="100.0" velocity="100.0" lower="-0.3490658503988659" upper="0.3490658503988659" />
    <parent link="mano_left_palm" />
    <child link="mano_left_index1y" />
    <axis xyz="0. -1. 0." />
    <origin xyz="-0.08809724664019486 -0.0052003570684035555 -0.02068598903709729" rpy="0.0 1.5656545707276812 -3.0830557190223242" />
  </joint>
  <joint name="mano_left_j_index1x" type="revolute">
    <limit effort="100.0" velocity="100.0" lower="-0.17453292519943295" upper="1.5707963267948966" />
    <parent link="mano_left_index1y" />
    <child link="mano_left_index1x" />
    <axis xyz="-1. 0. 0." />
    <origin xyz="0.0 0.0 0.0" rpy="0.0 0.0 0.0" />
  </joint>
  <joint name="mano_left_j_index2" type="revolute">
    <limit effort="100.0" velocity="100.0" lower="0.0" upper="1.7453292519943295" />
    <parent link="mano_left_index1x" />
    <child link="mano_left_index2" />
    <axis xyz="-1. 0. 0." />
    <origin xyz="0.0023835711672753985 -0.005914318759078097 0.03237654210665609" rpy="-5.985723906621881e-19 6.835640390420038e-19 -6.486977305262269e-21" />
  </joint>
  <joint name="mano_left_j_index3" type="revolute">
    <limit effort="100.0" velocity="100.0" lower="0.0" upper="1.7453292519943295" />
    <parent link="mano_left_index2" />
    <child link="mano_left_index3" />
    <axis xyz="-1. 0. 0." />
    <origin xyz="-2.1969386803155346e-21 1.0054815357582629e-19 0.022194219361846432" rpy="-5.985723906621881e-19 6.835640390420038e-19 -6.486977305262269e-21" />
  </joint>
  <joint name="mano_left_j_middle1y" type="revolute">
    <limit effort="100.0" velocity="100.0" lower="-0.3490658503988659" upper="0.5235987755982988" />
    <parent link="mano_left_palm" />
    <child link="mano_left_middle1y" />
    <axis xyz="0. -1. 0." />
    <origin xyz="-0.09466044139183748 -0.0014789633509431728 0.0033575408143170205" rpy="0.10838501782646781 1.399488824140411 -2.9769988584801235" />
  </joint>
  <joint name="mano_left_j_middle1x" type="revolute">
    <limit effort="100.0" velocity="100.0" lower="-0.17453292519943295" upper="1.5707963267948966" />
    <parent link="mano_left_middle1y" />
    <child link="mano_left_middle1x" />
    <axis xyz="-1. 0. 0." />
    <origin xyz="0.0 0.0 0.0" rpy="0.0 0.0 0.0" />
  </joint>
  <joint name="mano_left_j_middle2" type="revolute">
    <limit effort="100.0" velocity="100.0" lower="0.0" upper="1.7453292519943295" />
    <parent link="mano_left_middle1x" />
    <child link="mano_left_middle2" />
    <axis xyz="-1. 0. 0." />
    <origin xyz="-0.0003207158897834246 -0.003555264565700651 0.031533781277300055" rpy="7.187502047679508e-19 -1.1776617696394585e-17 -1.1633025402259818e-18" />
  </joint>
  <joint name="mano_left_j_middle3" type="revolute">
    <limit effort="100.0" velocity="100.0" lower="0.0" upper="1.7453292519943295" />
    <parent link="mano_left_middle2" />
    <child link="mano_left_middle3" />
    <axis xyz="-1. 0. 0." />
    <origin xyz="-5.609489609703704e-20 -7.277896970840872e-20 0.023275512883098835" rpy="7.187502047679508e-19 -1.1776617696394585e-17 -1.1633025402259818e-18" />
  </joint>
  <joint name="mano_left_j_pinky1y" type="revolute">
    <limit effort="100.0" velocity="100.0" lower="-0.3490658503988659" upper="0.6981317007977318" />
    <parent link="mano_left_palm" />
    <child link="mano_left_pinky1y" />
    <axis xyz="0. -1. 0." />
    <origin xyz="-0.0687869720598841 -0.00994032882044861 0.04320934200328496" rpy="-0.4325014617037457 0.9265283135189503 2.661490603166245" />
  </joint>
  <joint name="mano_left_j_pinky1x" type="revolute">
    <limit effort="100.0" velocity="100.0" lower="-0.17453292519943295" upper="1.5707963267948966" />
    <parent link="mano_left_pinky1y" />
    <child link="mano_left_pinky1x" />
    <axis xyz="-1. 0. 0." />
    <origin xyz="0.0 0.0 0.0" rpy="0.0 0.0 0.0" />
  </joint>
  <joint name="mano_left_j_pinky2" type="revolute">
    <limit effort="100.0" velocity="100.0" lower="0.0" upper="1.7453292519943295" />
    <parent link="mano_left_pinky1x" />
    <child link="mano_left_pinky2" />
    <axis xyz="-1. 0. 0." />
    <origin xyz="-0.0009123243154268479 -0.0011282837702486126 0.021062001859487044" rpy="2.484200750483751e-17 7.081513656750915e-17 -2.6504116429611938e-17" />
  </joint>
  <joint name="mano_left_j_pinky3" type="revolute">
    <limit effort="100.0" velocity="100.0" lower="0.0" upper="1.7453292519943295" />
    <parent link="mano_left_pinky2" />
    <child link="mano_left_pinky3" />
    <axis xyz="-1. 0. 0." />
    <origin xyz="-1.8952144180532274e-18 2.2152413969868993e-19 0.01894688789602988" rpy="2.484200750483751e-17 7.081513656750915e-17 -2.6504116429611938e-17" />
  </joint>
  <joint name="mano_left_j_ring1y" type="revolute">
    <limit effort="100.0" velocity="100.0" lower="-0.3490658503988659" upper="0.5235987755982988" />
    <parent link="mano_left_palm" />
    <child link="mano_left_ring1y" />
    <axis xyz="0. -1. 0." />
    <origin xyz="-0.08173555442881024 -0.003957421152865242 0.026673193033088197" rpy="-0.3794310720777505 1.2328253203111788 2.8133517240851353" />
  </joint>
  <joint name="mano_left_j_ring1x" type="revolute">
    <limit effort="100.0" velocity="100.0" lower="-0.17453292519943295" upper="1.5707963267948966" />
    <parent link="mano_left_ring1y" />
    <child link="mano_left_ring1x" />
    <axis xyz="-1. 0. 0." />
    <origin xyz="0.0 0.0 0.0" rpy="0.0 0.0 0.0" />
  </joint>
  <joint name="mano_left_j_ring2" type="revolute">
    <limit effort="100.0" velocity="100.0" lower="0.0" upper="1.7453292519943295" />
    <parent link="mano_left_ring1x" />
    <child link="mano_left_ring2" />
    <axis xyz="-1. 0. 0." />
    <origin xyz="0.00429786987999866 -0.003563675567715413 0.028298309378744307" rpy="6.026737690030247e-18 3.508963367964836e-17 -1.7519875374215658e-17" />
  </joint>
  <joint name="mano_left_j_ring3" type="revolute">
    <limit effort="100.0" velocity="100.0" lower="0.0" upper="1.7453292519943295" />
    <parent link="mano_left_ring2" />
    <child link="mano_left_ring3" />
    <axis xyz="-1. 0. 0." />
    <origin xyz="-7.238679066856496e-20 2.4155957590579026e-19 0.02478587029620925" rpy="6.026737690030247e-18 3.508963367964836e-17 -1.7519875374215658e-17" />
  </joint>
  <joint name="mano_left_j_thumb1y" type="revolute">
    <limit effort="100.0" velocity="100.0" lower="-0.17453292519943295" upper="2.6179938779914944" />
    <parent link="mano_left_palm" />
    <child link="mano_left_thumb1y" />
    <axis xyz="0. -1. 0." />
    <origin xyz="-0.024089706802642025 -0.015522334541875703 -0.025812847288082738" rpy="-0.7270385771615225 1.451914435932513 -2.4542043209348736" />
  </joint>
  <joint name="mano_left_j_thumb1z" type="revolute">
    <limit effort="100.0" velocity="100.0" lower="-0.6981317007977318" upper="0.6981317007977318" />
    <parent link="mano_left_thumb1y" />
    <child link="mano_left_thumb1z" />
    <axis xyz="0. 0. -1." />
    <origin xyz="0.0 0.0 0.0" rpy="0.0 0.0 0.0" />
  </joint>
  <joint name="mano_left_j_thumb2" type="revolute">
    <limit effort="100.0" velocity="100.0" lower="0.0" upper="1.7453292519943295" />
    <parent link="mano_left_thumb1z" />
    <child link="mano_left_thumb2" />
    <axis xyz="-1. 0. 0." />
    <origin xyz="0.02526494873869172 -0.017595730026252792 -1.0660017461924156e-19" rpy="1.1705944339598562 -0.7898458524685564 0.9959904350807831" />
  </joint>
  <joint name="mano_left_j_thumb3" type="revolute">
    <limit effort="100.0" velocity="100.0" lower="0.0" upper="1.7453292519943295" />
    <parent link="mano_left_thumb2" />
    <child link="mano_left_thumb3" />
    <axis xyz="-1. 0. 0." />
    <origin xyz="1.6439906908155651e-19 1.0686676358921293e-18 0.027094189966248017" rpy="3.586194595879372e-17 -2.2299700610673483e-17 5.828722753684352e-18" />
  </joint>
<joint name="human_to_left_mano" type="fixed"><origin xyz="0 0 0" rpy="-1.5708 0 1.5708" /><parent link="left_hand" /><child link="mano_left_left_hand_wrist" /></joint></robot>